Workbook
Name Print_Area_0_0: 'Check List'!$A$1:$V$35

Sheet Check List
C1: REGISTRO | W1: REG-IC.:__________
C2: CHECK LIST - CAMINHÃO DE PINTOS DE UM DIA | W2: PAG.01 de 01
C3: INCUBATÓRIO - S.P | W3: DATA CRIAÇÃO: 28/02/22 REV.: 00 ÚLTIMA REV.:
A4: LEGENDA: C (CONFORME) / NC (NÃO CONFORME) / N.A (NÃO SE APLICA)
A5: PARA USO DA LOGÍSTICA
A7: SAÍDA | B7: DATA: | F7: HORA: | G7: 375 | I7: PREFIXO(VEÍCULO): | N7: PLACA: | R7: MOTORISTA: | X7: OPERAÇÃO INCUBATÓRIO: | Z7: JULIANA MONTEIRO
A8: RETORNO | B8: DATA: | F8: HORA: | I8: PREFIXO(VEÍCULO): | N8: PLACA: | R8: MOTORISTA: | X8: OPERAÇÃO INCUBATÓRIO: | Z8: JULIANA MONTEIRO
A9: DOCUMENTAÇÃO | J9: SAÍDA | N9: RETORNO | R9: OBSERVAÇÕES:
A10: CRLV | J10: C | K10: X | L10: NC | N10: C | O10: X | P10: NC
A11: CERTIFICADO DE CRONOTACÓGRAFO | J11: C | K11: X | L11: NC | N11: C | O11: X | P11: NC
A12: AET | J12: C | K12: X | L12: NC | N12: C | O12: X | P12: NC
A13: CARTÃO COMBUSTÍVEL | J13: C | K13: X | L13: NC | N13: C | O13: X | P13: NC
A14: KIT SEGURANÇA | J14: SAÍDA | N14: RETORNO | Q14: OBSERVAÇÃO | R14: OBSERVAÇÕES:
A15: CINTO DE SEGURANÇA | J15: C | K15: X | L15: NC | N15: C | O15: X | P15: NC
A16: EXTINTOR | J16: C | K16: X | L16: NC | N16: C | O16: X | P16: NC
A17: MACACO HIDRÁULICO | J17: C | K17: X | L17: NC | N17: C | O17: X | P17: NC
A18: CHAVE DE RODA | J18: C | K18: X | L18: NC | N18: C | O18: X | P18: NC
A19: TRIÂNGULO | J19: C | K19: X | L19: NC | N19: C | O19: X | P19: NC
A20: ELÉTRICA / LANTERNAGEM | J20: SAÍDA | N20: RETORNO | Q20: OBSERVAÇÃO | R20: OBSERVAÇÕES:
A21: FAROL LD / LE | J21: C | K21: X | L21: NC | N21: C | O21: X | P21: NC
A22: RETROVISOR | J22: C | K22: X | L22: NC | N22: C | O22: X | P22: NC
A23: PARABRISA | J23: C | K23: X | L23: NC | N23: C | O23: X | P23: NC
A24: LIMPADOR PARABRISA | J24: C | K24: X | L24: NC | N24: C | O24: X | P24: NC
A25: BUZINA A AR / ELÉTRICA | J25: C | K25: X | L25: NC | N25: C | O25: X | P25: NC
A26: LANTERNA TRASEIRA LD / LE | J26: C | K26: X | L26: NC | N26: C | O26: X | P26: NC
A27: DIVERSOS | J27: SAÍDA | N27: RETORNO | Q27: OBSERVAÇÃO | R27: OBSERVAÇÕES:
A28: LACRE DA PLACA | J28: C | K28: X | L28: NC | N28: C | O28: X | P28: NC
A29: TANQUE DE COMBUSTÍVEL (PENEIRA) | J29: C | K29: X | L29: NC | N29: C | O29: X | P29: NC
A30: SISTEMA DE ÁGUA | J30: C | K30: X | L30: NC | N30: C | O30: X | P30: NC
A31: PNEUS | J31: SAÍDA | N31: RETORNO | Q31: OBSERVAÇÃO | R31: OBSERVAÇÕES:
A32: STEP | J32: C | K32: X | L32: NC | N32: C | O32: X | P32: NC
A34: 1-) O funcionamento do sistema de ventilação está conforme? | J34: X | K34: SIM | M34: NÃO | O34: N.A
A35: 2-) O funcionamento do sistema de exaustão está conforme? | J35: X | K35: SIM | M35: NÃO | O35: N.A
A36: 3-) O funcionamento do sistema de aquecimento está conforme? | J36: X | K36: SIM | M36: NÃO | O36: N.A
A37: 4-) O funcionamento do sistema de umidificação está conforme? | J37: X | K37: SIM | M37: NÃO | O37: N.A
A38: 5-) O funcionamento da parte elétrica está conforme? | J38: X | K38: SIM | M38: NÃO | O38: N.A
A39: 6-) A carroceria do baú está limpa e em bom estado de conservação? | J39: X | K39: SIM | M39: NÃO | O39: N.A
A40: 7-) O compartimento interno do baú encontra-se limpo e em bom estado de conservação? | J40: X | K40: SIM | M40: NÃO | O40: N.A
A41: 8-) As divisórias de sustentação das caixas estão conformes? | J41: X | K41: SIM | M41: NÃO | O41: N.A
A42: MANOBRISTA CIALNE:
...

Sheet EXPEDIÇÃO
C1: REGISTRO DE EXPEDIÇÃO DE PINTOS DE UM DIA | AB1: REG-IC.:____
AB2: PAG.01 de 01
C3: CIALNE - INCUBATÓRIO I | AB3: REV.: 00
A4: DATA DA CRIAÇÃO.: 28/02/22 | P4: DATA DA ÚLTIMA REVISÃO: 26/02/2026
A6: DATA DA EXPEDIÇÃO: | C6: ='Check List'!C48 -> 0 | F6: TRANSPORTADORA: | J6: ='Check List'!I48 -> CIALNE | Q6: PREFIXO(VEÍCULO): | T6: ='Check List'!L7 -> 0 | W6: PLACA: | AA6: ='Check List'!P7 -> 0
A8: SITUAÇÃO DE INSPEÇÃO * | C8: APROVADO | F8: Autorização para carregamento em caso "REPROVAÇÃO": | P8: Motivo da Reprovação: | AA8: Nº Lacre (pós carregameto)
A9: * Se "reprovado", a liberação do veículo para carregamento somente ocorrerá após substituição e ou conserto do veículo, salvo se o departamento comercial ou veterinário responsável pelo incubatóio liberar o veículo reprovado para carregamento relatando motivos da liberação e assinando como responsável pela autorização. | AA9: ='Check List'!X50 -> 0
F10: Comercial / PCP | L10: Veterinário | P10: Horário programado X realizado
F11: Visto: | L11: Visto: | P11: Envio de Remesas | Q11: Solicitação de Notas Fiscais | R11: Envio das NOTAS FISCAIS. | T11: Envio dos GTA's. | V11: Envio do MDFE | Y11: Previsão de carregamento | AA11: Início de carregamento | AC11: Horário término do carregamento da carga:
F12: Motivo pela liberação | L12: Motivo pela liberação
A15: CLIENTE | D15: Volume de Pintos | F15: CAIXAS DE PLÁSTICAS | H15: CAIXAS DE PAPELÃO | J15: Preço (Unid.) | L15: Nota Fiscal | N15: GTA | P15: Cidade | R15: Carga Rotulada | T15: Uso de Hidratante | V15: Número de Pintos M/R nas caixas | Z15: Nº Pintos Repostos | AB15: LOTE (s)
R16: Sim | S16: Não | T16: Sim | U16: Não | V16: Nº * | X16: %
J34: .
A36: * Após o carregamento da carga, realizar a contagem dos pintos, não conformes segregados e se o % retirado for > 0,08%, deve-se comunicar com R.T / ENCARREGADO responsável antes de liberar veículo carregado
A37: Observações do carregamento | S37: Conferência da (s) caixa (s) durante carregamento pelo (s) motorista (s): | X37: X | Y37: SIM | AB37: NÃO
Q40: .
A41: TOTAL CXS PLÁSTICAS | C41: =SUM(F17:F35) -> 0 | D41: TOTAL CXS PAPELÃO: | H41: =SUM(H17:H35) -> 0 | J41: TOTAL DE TAMPAS: | P41: VOLUME PROGRAMADO NA INCUBAÇÃO: | S41: 0 | V41: VOLUME TOTAL DE PINTOS: | AA41: =SUM(D17:D35) -> 0
A42: CONFERÊNCIA DOS DADOS PERTINENTES A (S) CARGAS (S) E CIENTE DE APROVAÇÃO DO (S) MOTORISTA (S) | D42: MOTORISTA (S) | S42: ASSINATURA (S)
D43: ='Check List'!D64 -> 0
D44: ='Check List'!D65 -> 0
A45: RESPONSÁVEL PELA EXPEDIÇÃO DAS CARGAS: | D45: ='Check List'!D67 -> JULIANA MONTEIRO | M45: CARGO: | P45: ='Check List'!M67 -> AUX. PRODUÇAO | S45: ASSINATURA:

Sheet TERMO DE CAIXAS
A1: COMPANHIA DE ALIMENTOS DO NORDESTE – CIALNE
A2: Avenida Presidente Costa e Silva, 2067 – Mondubim
A3: Fortaleza – CE
A4: CEP : 60.761-190
A5: TEL : (85) 3477-2700
A7: TERMO DE RESPONSABILIDADE
A8: CIALNE I
A9: Controle de Retirada
A11: Eu,
A12: Representante legal da empresa | D12: =EXPEDIÇÃO!A17 -> 0
A13: recebi da COMPANHIA DE ALIMENTOS DO NORDESTE - CIALNE I
A14: A quantidade de | B14: 113 | C14: Caixas e | E14: 0 | F14: tampas para transporte de pintos de 1 dia.
A15: No ato da devolução, comprometo – me a entregá – las em perfeito estado,
A16: salvo o degaste normal do uso.
A17: Estou ciente de que os danos provocados por maus tratos ou em caso de perda ou extravio,
A18: os valores correspondentes serão cobrados .
A19: Motorista Responsável: | C19: =EXPEDIÇÃO!D43 -> 0
A20: Motorista Responsável: | C20: =EXPEDIÇÃO!D44 -> 0
A21: Nº de CP: | B21: =EXPEDIÇÃO!T6 -> 0 | D21: Placa : | E21: =EXPEDIÇÃO!AA6 -> 0
A22: Data de retirada do Incubatório: | D22: =EXPEDIÇÃO!C6 -> 0
A23: Local de Entrega: | C23: ='[1]05.08.2026'!J12 -> zona rural
A25: Controle de Retorno
A27: Vieram : | D27: Ficaram :
A28: Data de Retorno :
A29: Quantidades de Caixas :
A30: Conferente Responsável :
A31: Motorista Responsável :
A32: OBSERVAÇÃO:
A36: Comprovante de Entrega no Incubatório
A37: Motoristas | B37: =C19 -> 0 | G37: Origem: | H37: =A8 -> CIALNE I
A38: Motoristas | B38: =C20 -> 0
A39: Nº de CP: | B39: =B21 -> 0 | D39: Placa : | E39: =E21 -> 0
A40: Quant. de Caixas : | B40: =B14 -> 113 | D40: Cliente : | E40: =D12 -> 0
A41: Data de Saída do Incubatório: | C41: =NOW() -> 46240.654 | F41: Data de Retorno:
A42: Colaborador Logística: | E42: Recebedor no incubatório:
A47: COMPANHIA DE ALIMENTOS DO NORDESTE – CIALNE
A48: Avenida Presidente Costa e Silva, 2067 – Mondubim
A49: Fortaleza – CE
A50: CEP : 60.761-190
A51: TEL : (85) 3477-2700
...

Sheet MOTORISTAS
A3: CHAPA | B3: COLABORADOR
A4: 14646 | B4: AFONSO CELSO FREIRE DE AMORIM
A5: 19702 | B5: ALDENE TITO DA SILVA
A6: 17114 | B6: ALEXANDRE OLIVEIRA LIMA
A7: 16964 | B7: ANDRE LUIZ NOBRE LEAL
A8: 19588 | B8: ANTONIO ELIANO DOS SANTOS LIMA
A9: 17440 | B9: ANTONIO FERNANDO MARTINS ROCHA
A10: 17450 | B10: ANTONIO FLAVIO DE MORAIS SANTOS
A11: 4006 | B11: ANTONIO HELIO GOMES RODRIGUES
A12: 19666 | B12: ANTONIO JOSE SILVA DOS SANTOS
A13: 14594 | B13: ANTONIO PESSOA DE SOUSA
A14: 15944 | B14: ANTONIO REGIS FERREIRA DA SILVA
A15: 3261 | B15: CESAR LIMA DA PENHA
... A41: 19305 | B41: VALBER ROQUE ALVES
B42: JOÃO DANIEL DE SOUSA CRUZ
B43: LUIZ WAGNER RIBEIRO ARAUJO

Sheet CAMINHÃO
A1: PLACAS DOS CAMINHÕES
A2: CP | B2: PLACA
A3: 320 | B3: POU – 2737
A4: 322 | B4: POJ – 6877
A5: 371 | B5: PNV – 1H72
A6: 372 | B6: PNZ – 7A12
A7: 373 | B7: PNV – 1712
A8: 374 | B8: POV – 8I37
A9: 375 | B9: PNY – 4D62
A10: 376 | B10: POW - 2857
A11: 377 | B11: POW – 2247
A12: 399 | B12: RIF - 8B00
A13: 403 | B13: POO - 3H52
A14: 404 | B14: PNX – 6533
... A27: 512 | B27: THO - 6C10
